Workbook

Sheet READ ME
A1: Canal Zone GIS - relational model (places / sources / attestations) + density + map modes
A3: TAB COLOURS (bottom of the window):
A4: Red = enter your core data here: Coordinates, places, sources, attestations.
A5: Orange = you add to these occasionally: Corpus, Coverage, relations, Lists, Feature Checklist.
A6: Grey / uncoloured = auto-calculated or reference only - do not type in these.
A7: - New tabs: "Map Modes + Rendering" (the 6 views as an app spec) and an updated Selection Matrix on archival visibility.
A9: The archival-density caution (your insight, kept central):
A10: Density = how visible a place is in surviving archives, NOT how historically important it was. Displaced and Afro-Caribbean
A11: communities were systematically under-recorded, so thin density often marks the MOST important silences. The model never
A12: equates density with importance - there is deliberately no "importance" score.
A14: "Unmapped but known" is built in:
A15: Any place with spatial_certainty = Unknown keeps its full record and its render_as becomes "Unplotted (unlocated panel)".
... A22: Green columns are AUTO (formulas) - do not type in them. Coordinates stay blank until georeferenced (do not guess).

Sheet Coordinates
A1: Coordinate entry. place_id / name / scale fill IN AUTOMATICALLY from the places sheet. You only type lat + lng (yellow). Do NOT sort this sheet (rows track the places sheet by position).
A2: place_id | B2: name | C2: scale | D2: lat | E2: lng | F2: coord_source | G2: status
A3: =IF(places!$A2="","",places!$A2) -> CZ-001 | B3: =IF(places!$A2="","",places!$B2) -> Matachin | C3: =IF(places!$A2="","",places!$Y2) -> Town | D3: 9.10975 | E3: -79.70699 | F3: ICC1911 property map | G3: surveyed from ICC1911 georef, ±400m [CORRECTED 2026-09-08: earlier paste had a transcription error]
A4: =IF(places!$A3="","",places!$A3) -> CZ-002 | B4: =IF(places!$A3="","",places!$B3) -> Barbacoas | C4: =IF(places!$A3="","",places!$Y3) -> Town | D4: 9.10938 | E4: -79.76765 | F4: ICC Surveys 1905-06 Map No.2 | G4: surveyed from SURVEYS1908 georef (bridge site), ±250m
A5: =IF(places!$A4="","",places!$A4) -> CZ-003 | B5: =IF(places!$A4="","",places!$B4) -> Cruces | C5: =IF(places!$A4="","",places!$Y4) -> Town | D5: 9.124 | E5: -79.68765 | F5: ICC Surveys 1905-06 Map No.2 | G5: surveyed from SURVEYS1908 georef, ±250m
A6: =IF(places!$A5="","",places!$A5) -> CZ-004 | B6: =IF(places!$A5="","",places!$B5) -> Ahorca Lagarto | C6: =IF(places!$A5="","",places!$Y5) -> Town | D6: 9.21291 | E6: -79.876 | F6: ICC Surveys 1905-06 Map No.1 | G6: surveyed from SURVEYS1908 georef, ±250m
A7: =IF(places!$A6="","",places!$A6) -> CZ-005 | B7: =IF(places!$A6="","",places!$B6) -> Caimito | C7: =IF(places!$A6="","",places!$Y6) -> Town | D7: 9.13067 | E7: -79.77984 | F7: ICC1911 property map | G7: surveyed from ICC1911 georef (label), ±500m [CORRECTED 2026-09-08: earlier paste had a transcription error]
A8: =IF(places!$A7="","",places!$A7) -> CZ-006 | B8: =IF(places!$A7="","",places!$B7) -> Santa Cruz | C8: =IF(places!$A7="","",places!$Y7) -> Town | D8: 9.11687 | E8: -79.6977 | F8: ICC1911 property map | G8: surveyed from ICC1911 georef (label), ±400m [CORRECTED 2026-09-08: earlier paste had a transcription error]
A9: =IF(places!$A8="","",places!$A8) -> CZ-007 | B9: =IF(places!$A8="","",places!$B8) -> Bailamonos | C9: =IF(places!$A8="","",places!$Y8) -> Town | D9: 9.11008 | E9: -79.76486 | F9: 1862 Rio Chagres plano | G9: surveyed from CHAGRES1867 georef (tract, no pueblo symbol), ±800m
A10: =IF(places!$A9="","",places!$A9) -> CZ-008 | B10: =IF(places!$A9="","",places!$B9) -> Cruz de Juan Gallego | C10: =IF(places!$A9="","",places!$Y9) -> Town | D10: 9.20472 | E10: -79.86746 | F10: 1862 Rio Chagres plano | G10: surveyed from CHAGRES1867 georef (creek label only), ±1km
A11: =IF(places!$A10="","",places!$A10) -> CZ-009 | B11: =IF(places!$A10="","",places!$B10) -> Old Gatun | C11: =IF(places!$A10="","",places!$Y10) -> Town | D11: 9.26871 | E11: -79.92906 | F11: ICC Surveys 1905-06 Map No.1 | G11: surveyed from SURVEYS1908 georef (village drawn), ±250m
A12: =IF(places!$A11="","",places!$A11) -> CZ-010 | B12: =IF(places!$A11="","",places!$B11) -> New Gatun | C12: =IF(places!$A11="","",places!$Y11) -> Town | D12: 9.27471 | E12: -79.91621 | F12: ICC1911 property map | G12: surveyed from ICC1911 georef (building cluster), ±200m
A13: =IF(places!$A12="","",places!$A12) -> CZ-011 | B13: =IF(places!$A12="","",places!$B12) -> Empire | C13: =IF(places!$A12="","",places!$Y12) -> Town | D13: 9.061825 | E13: -79.671171 | F13: ICC Surveys 1905-06 Map No.3 | G13: surveyed from SURVEYS1908 Map No.3 georef (the arbitration source), ±150m; re-anchored EMPIRE plan footprint agrees within 230 m [replaced 2026-09-14: previous value was the stale pre-re-anchor EMPIRE-chain position the 2026-09-09 re-anchor never propagated to CZ-011 itself]
A14: =IF(places!$A13="","",places!$A13) -> CZ-012 | B14: =IF(places!$A13="","",places!$B13) -> Gorgona | C14: =IF(places!$A13="","",places!$Y13) -> Town | D14: 9.11401 | E14: -79.72415 | F14: Map of Gorgona 1908 (saloon) | G14: surveyed from GORGONA plan georef; SURVEYS1908 agrees within 100m, ±400m abs
... A18: =IF(places!$A17="","",places!$A17) -> CZ-016 | B18: =IF(places!$A17="","",places!$B17) -> Bohio | C18: =IF(places!$A17="","",places!$Y17) -> Town | D18: 9.1898 | E18: -79.85598 | F18: ICC Surveys 1905-06 Map No.1 | G18: surveyed from SURVEYS1908 georef (village drawn), ±250m
A19: =IF(places!$A18="","",places!$A18) -> CZ-101 | B19: =IF(places!$A18="","",places!$B18) -> Empire Hospital | C19: =IF(places!$A18="","",places!$Y18) -> Site/Institution | D19: 9.0715 | E19: -79.6818 | G19: placeholder
A20: =IF(places!$A19="","",places!$A19) -> CZ-102 | B20: =IF(places!$A19="","",places!$B19) -> Empire Commissary | C20: =IF(places!$A19="","",places!$Y19) -> Site/Institution | D20: 9.062558 | E20: -79.671553 | F20: General map of Empire (re-anchored) | G20: surveyed from EMPIRE plan georef re-anchored to SURVEYS1908_MAP3, +-200m
A21: =IF(places!$A20="","",places!$A20) -> CZ-103 | B21: =IF(places!$A20="","",places!$B20) -> Empire Clubhouse & Cinema | C21: =IF(places!$A20="","",places!$Y20) -> Building | D21: 9.0719 | E21: -79.6809 | G21: placeholder
A22: =IF(places!$A21="","",places!$A21) -> CZ-104 | B22: =IF(places!$A21="","",places!$B21) -> Empire Silver Quarters | C22: =IF(places!$A21="","",places!$Y21) -> Neighborhood | D22: 9.0702 | E22: -79.6822 | G22: placeholder
A23: =IF(places!$A22="","",places!$A22) -> CZ-105 | B23: =IF(places!$A22="","",places!$B22) -> Empire Gold Quarters | C23: =IF(places!$A22="","",places!$Y22) -> Neighborhood | D23: 9.0723 | E23: -79.68 | G23: placeholder
A24: =IF(places!$A23="","",places!$A23) -> CZ-106 | B24: =IF(places!$A23="","",places!$B23) -> Empire Plaza | C24: =IF(places!$A23="","",places!$Y23) -> Site/Institution | D24: 9.060552 | E24: -79.672322 | F24: General map of Empire (re-anchored) | G24: surveyed from EMPIRE plan georef re-anchored to SURVEYS1908_MAP3, +-200m
A25: =IF(places!$A24="","",places!$A24) -> CZ-201 | B25: =IF(places!$A24="","",places!$B24) -> Nuevo Emperador (present-day) | C25: =IF(places!$A24="","",places!$Y24) -> Town | D25: 9.07 | E25: -79.679 | G25: placeholder
A26: =IF(places!$A25="","",places!$A25) -> CZ-202 | B26: =IF(places!$A25="","",places!$B25) -> Modern roadway segment | C26: =IF(places!$A25="","",places!$Y25) -> Infrastructure | D26: 9.0695 | E26: -79.677 | G26: placeholder
A27: =IF(places!$A26="","",places!$A26) -> CZ-107 | B27: =IF(places!$A26="","",places!$B26) -> Empire Church / Chapel | C27: =IF(places!$A26="","",places!$Y26) -> Site/Institution | D27: 9.06283 | E27: -79.670234 | F27: General map of Empire (re-anchored) | G27: surveyed from EMPIRE plan georef re-anchored to SURVEYS1908_MAP3, +-200m (Cath. Church, 2nd-pass find)
A28: =IF(places!$A27="","",places!$A27) -> CZ-108 | B28: =IF(places!$A27="","",places!$B27) -> Empire Cemetery | C28: =IF(places!$A27="","",places!$Y27) -> Site/Institution | D28: 9.0698 | E28: -79.683 | G28: placeholder
A29: =IF(places!$A28="","",places!$A28) -> CZ-109 | B29: =IF(places!$A28="","",places!$B28) -> Empire School | C29: =IF(places!$A28="","",places!$Y28) -> Site/Institution | D29: 9.063286 | E29: -79.674734 | F29: General map of Empire (re-anchored) | G29: surveyed from EMPIRE plan georef re-anchored to SURVEYS1908_MAP3, +-200m
A30: =IF(places!$A29="","",places!$A29) -> CZ-017 | B30: =IF(places!$A29="","",places!$B29) -> Cristobal | C30: =IF(places!$A29="","",places!$Y29) -> Town | D30: 9.35589 | E30: -79.9006 | F30: ICC1911 property map | G30: surveyed from ICC1911 georef, ±300m
A31: =IF(places!$A30="","",places!$A30) -> CZ-018 | B31: =IF(places!$A30="","",places!$B30) -> Ancon | C31: =IF(places!$A30="","",places!$Y30) -> Town | D31: 8.95941 | E31: -79.56199 | F31: ICC1909 zone map | G31: surveyed from ICC1909 georef (town dot), ±300m [CORRECTED 2026-09-08: earlier paste had a transcription error]
A32: =IF(places!$A31="","",places!$A31) -> CZ-019 | B32: =IF(places!$A31="","",places!$B31) -> Rio Grande | C32: =IF(places!$A31="","",places!$Y31) -> Town | D32: 9.03223 | E32: -79.66239 | F32: ICC1909 zone map | G32: surveyed from ICC1909 georef, ±300m
A33: =IF(places!$A32="","",places!$A32) -> CZ-020 | B33: =IF(places!$A32="","",places!$B32) -> Pedro Miguel | C33: =IF(places!$A32="","",places!$Y32) -> Town | D33: 9.02378 | E33: -79.60107 | F33: ICC1909 zone map | G33: surveyed from ICC1909 georef (town dot), ±300m [CORRECTED 2026-09-08: earlier paste had a transcription error]
A34: =IF(places!$A33="","",places!$A33) -> CZ-021 | B34: =IF(places!$A33="","",places!$B33) -> La Boca | C34: =IF(places!$A33="","",places!$Y33) -> Town | D34: 8.94776 | E34: -79.56447 | F34: ICC1911 property map | G34: surveyed from ICC1911 georef (drawn town labeled BALBOA), ±300m
A35: =IF(places!$A34="","",places!$A34) -> CZ-022 | B35: =IF(places!$A34="","",places!$B34) -> Corozal | C35: =IF(places!$A34="","",places!$Y34) -> Town | D35: 8.97957 | E35: -79.56824 | F35: ICC1911 property map | G35: surveyed from ICC1911 georef, ±300m [CORRECTED 2026-09-08: earlier paste had a transcription error]
A36: =IF(places!$A35="","",places!$A35) -> CZ-023 | B36: =IF(places!$A35="","",places!$B35) -> Frijoles | C36: =IF(places!$A35="","",places!$Y35) -> Town | D36: 9.16964 | E36: -79.80337 | F36: ICC Surveys 1905-06 Map No.2 | G36: surveyed from SURVEYS1908 georef (occupied village; abandoned site also recorded), ±250m
A37: =IF(places!$A36="","",places!$A36) -> CZ-024 | B37: =IF(places!$A36="","",places!$B36) -> Paraiso | C37: =IF(places!$A36="","",places!$Y36) -> Town | D37: 9.02697 | E37: -79.62499 | F37: ICC1909 zone map | G37: surveyed from ICC1909 georef, ±300m
A38: =IF(places!$A37="","",places!$A37) -> CZ-025 | B38: =IF(places!$A37="","",places!$B37) -> San Pablo | C38: =IF(places!$A37="","",places!$Y37) -> Town | D38: 9.11867 | E38: -79.78701 | F38: ICC Surveys 1905-06 Map No.2 | G38: surveyed from SURVEYS1908 georef (probable village; label at fold), ±400m
A39: =IF(places!$A38="","",places!$A38) -> CZ-026 | B39: =IF(places!$A38="","",places!$B38) -> Tabernilla | C39: =IF(places!$A38="","",places!$Y38) -> Town | D39: 9.13351 | E39: -79.81839 | F39: ICC1911 property map | G39: surveyed from ICC1911 georef; NOTE sources disagree up to 1.2km - see candidate CSVs
A40: =IF(places!$A39="","",places!$A39) -> CZ-027 | B40: =IF(places!$A39="","",places!$B39) -> Gamboa | C40: =IF(places!$A39="","",places!$Y39) -> Town | D40: 9.11327 | E40: -79.69404 | F40: ICC Surveys 1905-06 Map No.2 | G40: surveyed from SURVEYS1908 georef, ±300m
... A56: =IF(places!$A55="","",places!$A55) -> CZ-044 | B56: =IF(places!$A55="","",places!$B55) -> Juan Grande | C56: =IF(places!$A55="","",places!$Y55) -> Town | D56: 9.11773 | E56: -79.7401 | F56: ICC Surveys 1905-06 Map No.2 | G56: surveyed from SURVEYS1908 georef, ±250m
A57: =IF(places!$A56="","",places!$A56) -> CZ-045 | B57: =IF(places!$A56="","",places!$B56) -> Gatuncillo | C57: =IF(places!$A56="","",places!$Y56) -> Town
A58: =IF(places!$A57="","",places!$A57) -> CZ-046 | B58: =IF(places!$A57="","",places!$B57) -> Balboa Heights | C58: =IF(places!$A57="","",places!$Y57) -> Town | D58: 8.961086 | E58: -79.557709 | F58: PACIFIC1947 (pcc00008) | G58: surveyed from the 1947 Pacific Terminal Cities georef (Administration Building), ±150m
...

Sheet places
A1: place_id (PK) | B1: preferred_name | C1: variant_names | D1: place_type | E1: erasure_type | F1: erasure_mechanism | G1: historical_theme | H1: population_type | I1: start_date | J1: end_date | K1: date_certainty | L1: spatial_certainty | M1: render_as (auto) | N1: uncertainty_radius_m | O1: archival_traces (auto) | P1: n_map (auto) | Q1: n_image (auto) | R1: n_textual (auto) | S1: n_geom (auto) | T1: archival_visibility (auto) | U1: has_surveyed_coord (auto) | V1: shortlist_status | W1: priority | X1: notes | Y1: scale | Z1: parent_id (FK) | AA1: card_note
A2: CZ-001 | B2: Matachin | C2: Matachin; Bas Matachin | D2: Station | E2: Submerged | F2: Gatun Lake flooding | G2: Displacement | H2: Panamanian village | I2: pre-1850? | J2: 1911-1914 | K2: Approximate | L2: Low | M2: =IF($A2="","",IF($L2="High","Solid point",IF($L2="Medium","Point + buffer",IF($L2="Low","Translucent area",IF($L2="Disputed","Candidate points",IF($L2="Unknown","Unplotted (unlocated panel)","-")))))) -> Translucent area | N2: 300 | O2: =IF($A2="","",COUNTIF(attestations!$B$2:$B$2000,$A2)) -> 30 | P2: =IF($A2="","",COUNTIFS(attestations!$B$2:$B$2000,$A2,attestations!$R$2:$R$2000,"Map")) -> 3 | Q2: =IF($A2="","",COUNTIFS(attestations!$B$2:$B$2000,$A2,attestations!$R$2:$R$2000,"Image")) -> 1 | R2: =IF($A2="","",COUNTIFS(attestations!$B$2:$B$2000,$A2,attestations!$R$2:$R$2000,"Textual")) -> 7 | S2: =IF($A2="","",COUNTIFS(attestations!$B$2:$B$2000,$A2,attestations!$D$2:$D$2000,"Geometry (Setting)")) -> 7 | T2: =IF($A2="","",IF($O2>=6,"High",IF($O2>=3,"Medium",IF($O2>=1,"Low","None")))) -> High | U2: =IF($A2="","",IF(COUNTIFS(attestations!$B$2:$B$2000,$A2,attestations!$I$2:$I$2000,"Georeferenced map GCP")>0,"Y","N")) -> Y | V2: Candidate | X2: Railroad-era Chagres town. | Y2: Town
A3: CZ-002 | B3: Barbacoas | D3: Village | E3: Submerged | F3: Gatun Lake flooding | G3: Displacement | H3: Panamanian village | I3: pre-1844 | J3: 1911-1914 | K3: Approximate | L3: Low | M3: =IF($A3="","",IF($L3="High","Solid point",IF($L3="Medium","Point + buffer",IF($L3="Low","Translucent area",IF($L3="Disputed","Candidate points",IF($L3="Unknown","Unplotted (unlocated panel)","-")))))) -> Translucent area | N3: 400 | O3: =IF($A3="","",COUNTIF(attestations!$B$2:$B$2000,$A3)) -> 19 | P3: =IF($A3="","",COUNTIFS(attestations!$B$2:$B$2000,$A3,attestations!$R$2:$R$2000,"Map")) -> 1 | Q3: =IF($A3="","",COUNTIFS(attestations!$B$2:$B$2000,$A3,attestations!$R$2:$R$2000,"Image")) -> 1 | R3: =IF($A3="","",COUNTIFS(attestations!$B$2:$B$2000,$A3,attestations!$R$2:$R$2000,"Textual")) -> 6 | S3: =IF($A3="","",COUNTIFS(attestations!$B$2:$B$2000,$A3,attestations!$D$2:$D$2000,"Geometry (Setting)")) -> 5 | T3: =IF($A3="","",IF($O3>=6,"High",IF($O3>=3,"Medium",IF($O3>=1,"Low","None")))) -> High | U3: =IF($A3="","",IF(COUNTIFS(attestations!$B$2:$B$2000,$A3,attestations!$I$2:$I$2000,"Georeferenced map GCP")>0,"Y","N")) -> Y | V3: Candidate | X3: Bridge-site history. | Y3: Town
A4: CZ-003 | B4: Cruces | C4: Cruces; Las Cruces; Venta Cruz | D4: Village | E4: Submerged | F4: Gatun Lake flooding | G4: Displacement | H4: Panamanian village | I4: c.1530 | J4: 1911-1914 | K4: Approximate | L4: Low | M4: =IF($A4="","",IF($L4="High","Solid point",IF($L4="Medium","Point + buffer",IF($L4="Low","Translucent area",IF($L4="Disputed","Candidate points",IF($L4="Unknown","Unplotted (unlocated panel)","-")))))) -> Translucent area | N4: 400 | O4: =IF($A4="","",COUNTIF(attestations!$B$2:$B$2000,$A4)) -> 27 | P4: =IF($A4="","",COUNTIFS(attestations!$B$2:$B$2000,$A4,attestations!$R$2:$R$2000,"Map")) -> 3 | Q4: =IF($A4="","",COUNTIFS(attestations!$B$2:$B$2000,$A4,attestations!$R$2:$R$2000,"Image")) -> 1 | R4: =IF($A4="","",COUNTIFS(attestations!$B$2:$B$2000,$A4,attestations!$R$2:$R$2000,"Textual")) -> 8 | S4: =IF($A4="","",COUNTIFS(attestations!$B$2:$B$2000,$A4,attestations!$D$2:$D$2000,"Geometry (Setting)")) -> 6 | T4: =IF($A4="","",IF($O4>=6,"High",IF($O4>=3,"Medium",IF($O4>=1,"Low","None")))) -> High | U4: =IF($A4="","",IF(COUNTIFS(attestations!$B$2:$B$2000,$A4,attestations!$I$2:$I$2000,"Georeferenced map GCP")>0,"Y","N")) -> Y | V4: Candidate | W4: High | X4: Colonial trail terminus. | Y4: Town
A5: CZ-004 | B5: Ahorca Lagarto | D5: Hamlet | E5: Submerged | F5: Gatun Lake flooding | G5: Displacement | H5: Panamanian village | J5: 1911-1914 | K5: Unknown | L5: Medium | M5: =IF($A5="","",IF($L5="High","Solid point",IF($L5="Medium","Point + buffer",IF($L5="Low","Translucent area",IF($L5="Disputed","Candidate points",IF($L5="Unknown","Unplotted (unlocated panel)","-")))))) -> Point + buffer | N5: 250 | O5: =IF($A5="","",COUNTIF(attestations!$B$2:$B$2000,$A5)) -> 17 | P5: =IF($A5="","",COUNTIFS(attestations!$B$2:$B$2000,$A5,attestations!$R$2:$R$2000,"Map")) -> 1 | Q5: =IF($A5="","",COUNTIFS(attestations!$B$2:$B$2000,$A5,attestations!$R$2:$R$2000,"Image")) -> 0 | R5: =IF($A5="","",COUNTIFS(attestations!$B$2:$B$2000,$A5,attestations!$R$2:$R$2000,"Textual")) -> 6 | S5: =IF($A5="","",COUNTIFS(attestations!$B$2:$B$2000,$A5,attestations!$D$2:$D$2000,"Geometry (Setting)")) -> 5 | T5: =IF($A5="","",IF($O5>=6,"High",IF($O5>=3,"Medium",IF($O5>=1,"Low","None")))) -> High | U5: =IF($A5="","",IF(COUNTIFS(attestations!$B$2:$B$2000,$A5,attestations!$I$2:$I$2000,"Georeferenced map GCP")>0,"Y","N")) -> Y | V5: Candidate | X5: Name-only test case -> unlocated panel. | Y5: Town
A6: CZ-005 | B6: Caimito | D6: Hamlet | E6: Submerged | F6: Gatun Lake flooding | G6: Displacement | H6: Panamanian village | J6: 1911-1914 | K6: Unknown | L6: Low | M6: =IF($A6="","",IF($L6="High","Solid point",IF($L6="Medium","Point + buffer",IF($L6="Low","Translucent area",IF($L6="Disputed","Candidate points",IF($L6="Unknown","Unplotted (unlocated panel)","-")))))) -> Translucent area | N6: 500 | O6: =IF($A6="","",COUNTIF(attestations!$B$2:$B$2000,$A6)) -> 16 | P6: =IF($A6="","",COUNTIFS(attestations!$B$2:$B$2000,$A6,attestations!$R$2:$R$2000,"Map")) -> 1 | Q6: =IF($A6="","",COUNTIFS(attestations!$B$2:$B$2000,$A6,attestations!$R$2:$R$2000,"Image")) -> 1 | R6: =IF($A6="","",COUNTIFS(attestations!$B$2:$B$2000,$A6,attestations!$R$2:$R$2000,"Textual")) -> 6 | S6: =IF($A6="","",COUNTIFS(attestations!$B$2:$B$2000,$A6,attestations!$D$2:$D$2000,"Geometry (Setting)")) -> 1 | T6: =IF($A6="","",IF($O6>=6,"High",IF($O6>=3,"Medium",IF($O6>=1,"Low","None")))) -> High | U6: =IF($A6="","",IF(COUNTIFS(attestations!$B$2:$B$2000,$A6,attestations!$I$2:$I$2000,"Georeferenced map GCP")>0,"Y","N")) -> Y | V6: Candidate | Y6: Town
A7: CZ-006 | B7: Santa Cruz | D7: Hamlet | E7: Submerged | F7: Gatun Lake flooding | G7: Displacement | H7: Panamanian village | J7: 1911-1914 | K7: Unknown | L7: Low | M7: =IF($A7="","",IF($L7="High","Solid point",IF($L7="Medium","Point + buffer",IF($L7="Low","Translucent area",IF($L7="Disputed","Candidate points",IF($L7="Unknown","Unplotted (unlocated panel)","-")))))) -> Translucent area | N7: 400 | O7: =IF($A7="","",COUNTIF(attestations!$B$2:$B$2000,$A7)) -> 18 | P7: =IF($A7="","",COUNTIFS(attestations!$B$2:$B$2000,$A7,attestations!$R$2:$R$2000,"Map")) -> 2 | Q7: =IF($A7="","",COUNTIFS(attestations!$B$2:$B$2000,$A7,attestations!$R$2:$R$2000,"Image")) -> 1 | R7: =IF($A7="","",COUNTIFS(attestations!$B$2:$B$2000,$A7,attestations!$R$2:$R$2000,"Textual")) -> 6 | S7: =IF($A7="","",COUNTIFS(attestations!$B$2:$B$2000,$A7,attestations!$D$2:$D$2000,"Geometry (Setting)")) -> 3 | T7: =IF($A7="","",IF($O7>=6,"High",IF($O7>=3,"Medium",IF($O7>=1,"Low","None")))) -> High | U7: =IF($A7="","",IF(COUNTIFS(attestations!$B$2:$B$2000,$A7,attestations!$I$2:$I$2000,"Georeferenced map GCP")>0,"Y","N")) -> Y | V7: Candidate | Y7: Town
A8: CZ-007 | B8: Bailamonos | D8: Hamlet | E8: Submerged | F8: Gatun Lake flooding | G8: Displacement | H8: Panamanian village | J8: 1911-1914 | K8: Unknown | L8: Low | M8: =IF($A8="","",IF($L8="High","Solid point",IF($L8="Medium","Point + buffer",IF($L8="Low","Translucent area",IF($L8="Disputed","Candidate points",IF($L8="Unknown","Unplotted (unlocated panel)","-")))))) -> Translucent area | N8: 800 | O8: =IF($A8="","",COUNTIF(attestations!$B$2:$B$2000,$A8)) -> 20 | P8: =IF($A8="","",COUNTIFS(attestations!$B$2:$B$2000,$A8,attestations!$R$2:$R$2000,"Map")) -> 1 | Q8: =IF($A8="","",COUNTIFS(attestations!$B$2:$B$2000,$A8,attestations!$R$2:$R$2000,"Image")) -> 0 | R8: =IF($A8="","",COUNTIFS(attestations!$B$2:$B$2000,$A8,attestations!$R$2:$R$2000,"Textual")) -> 6 | S8: =IF($A8="","",COUNTIFS(attestations!$B$2:$B$2000,$A8,attestations!$D$2:$D$2000,"Geometry (Setting)")) -> 4 | T8: =IF($A8="","",IF($O8>=6,"High",IF($O8>=3,"Medium",IF($O8>=1,"Low","None")))) -> High | U8: =IF($A8="","",IF(COUNTIFS(attestations!$B$2:$B$2000,$A8,attestations!$I$2:$I$2000,"Georeferenced map GCP")>0,"Y","N")) -> Y | V8: Candidate | Y8: Town
A9: CZ-008 | B9: Cruz de Juan Gallego | D9: Hamlet | E9: Submerged | F9: Gatun Lake flooding | G9: Displacement | H9: Panamanian village | J9: 1911-1914 | K9: Unknown | L9: Low | M9: =IF($A9="","",IF($L9="High","Solid point",IF($L9="Medium","Point + buffer",IF($L9="Low","Translucent area",IF($L9="Disputed","Candidate points",IF($L9="Unknown","Unplotted (unlocated panel)","-")))))) -> Translucent area | N9: 1000 | O9: =IF($A9="","",COUNTIF(attestations!$B$2:$B$2000,$A9)) -> 15 | P9: =IF($A9="","",COUNTIFS(attestations!$B$2:$B$2000,$A9,attestations!$R$2:$R$2000,"Map")) -> 0 | Q9: =IF($A9="","",COUNTIFS(attestations!$B$2:$B$2000,$A9,attestations!$R$2:$R$2000,"Image")) -> 1 | R9: =IF($A9="","",COUNTIFS(attestations!$B$2:$B$2000,$A9,attestations!$R$2:$R$2000,"Textual")) -> 3 | S9: =IF($A9="","",COUNTIFS(attestations!$B$2:$B$2000,$A9,attestations!$D$2:$D$2000,"Geometry (Setting)")) -> 1 | T9: =IF($A9="","",IF($O9>=6,"High",IF($O9>=3,"Medium",IF($O9>=1,"Low","None")))) -> High | U9: =IF($A9="","",IF(COUNTIFS(attestations!$B$2:$B$2000,$A9,attestations!$I$2:$I$2000,"Georeferenced map GCP")>0,"Y","N")) -> Y | V9: Candidate | Y9: Town
A10: CZ-009 | B10: Old Gatun | C10: Gatun (old village); De Lesseps City | D10: Village | E10: Submerged | F10: Gatun Dam construction | G10: Displacement | H10: Mixed | I10: pre-1844 | J10: 1911-1912 | K10: Approximate | L10: Low | M10: =IF($A10="","",IF($L10="High","Solid point",IF($L10="Medium","Point + buffer",IF($L10="Low","Translucent area",IF($L10="Disputed","Candidate points",IF($L10="Unknown","Unplotted (unlocated panel)","-")))))) -> Translucent area | N10: 500 | O10: =IF($A10="","",COUNTIF(attestations!$B$2:$B$2000,$A10)) -> 28 | P10: =IF($A10="","",COUNTIFS(attestations!$B$2:$B$2000,$A10,attestations!$R$2:$R$2000,"Map")) -> 3 | Q10: =IF($A10="","",COUNTIFS(attestations!$B$2:$B$2000,$A10,attestations!$R$2:$R$2000,"Image")) -> 3 | R10: =IF($A10="","",COUNTIFS(attestations!$B$2:$B$2000,$A10,attestations!$R$2:$R$2000,"Textual")) -> 9 | S10: =IF($A10="","",COUNTIFS(attestations!$B$2:$B$2000,$A10,attestations!$D$2:$D$2000,"Geometry (Setting)")) -> 6 | T10: =IF($A10="","",IF($O10>=6,"High",IF($O10>=3,"Medium",IF($O10>=1,"Low","None")))) -> High | U10: =IF($A10="","",IF(COUNTIFS(attestations!$B$2:$B$2000,$A10,attestations!$I$2:$I$2000,"Georeferenced map GCP")>0,"Y","N")) -> Y | V10: Candidate | W10: High | X10: Under ~80 ft dam fill. Abandoned 1908; site submerged 1911-1912 (A-0079). | Y10: Town
A11: CZ-010 | B11: New Gatun | C11: New Gatun; Nuevo Gatun | D11: Town | E11: Relocated | F11: Railroad relocation | G11: Displacement | H11: Mixed | I11: 1908 | K11: Approximate | L11: Medium | M11: =IF($A11="","",IF($L11="High","Solid point",IF($L11="Medium","Point + buffer",IF($L11="Low","Translucent area",IF($L11="Disputed","Candidate points",IF($L11="Unknown","Unplotted (unlocated panel)","-")))))) -> Point + buffer | N11: 250 | O11: =IF($A11="","",COUNTIF(attestations!$B$2:$B$2000,$A11)) -> 17 | P11: =IF($A11="","",COUNTIFS(attestations!$B$2:$B$2000,$A11,attestations!$R$2:$R$2000,"Map")) -> 1 | Q11: =IF($A11="","",COUNTIFS(attestations!$B$2:$B$2000,$A11,attestations!$R$2:$R$2000,"Image")) -> 1 | R11: =IF($A11="","",COUNTIFS(attestations!$B$2:$B$2000,$A11,attestations!$R$2:$R$2000,"Textual")) -> 5 | S11: =IF($A11="","",COUNTIFS(attestations!$B$2:$B$2000,$A11,attestations!$D$2:$D$2000,"Geometry (Setting)")) -> 4 | T11: =IF($A11="","",IF($O11>=6,"High",IF($O11>=3,"Medium",IF($O11>=1,"Low","None")))) -> High | U11: =IF($A11="","",IF(COUNTIFS(attestations!$B$2:$B$2000,$A11,attestations!$I$2:$I$2000,"Georeferenced map GCP")>0,"Y","N")) -> Y | V11: Candidate | W11: Medium | X11: Receiving town. | Y11: Town
A12: CZ-011 | B12: Empire | C12: Empire; Emperador; Alto Emperador | D12: Town | E12: Depopulated-not flooded | F12: 1912 depopulation order | G12: Labor | H12: Mixed | I12: c.1880s | J12: 1912-1916 | K12: Approximate | L12: Medium | M12: =IF($A12="","",IF($L12="High","Solid point",IF($L12="Medium","Point + buffer",IF($L12="Low","Translucent area",IF($L12="Disputed","Candidate points",IF($L12="Unknown","Unplotted (unlocated panel)","-")))))) -> Point + buffer | N12: 300 | O12: =IF($A12="","",COUNTIF(attestations!$B$2:$B$2000,$A12)) -> 35 | P12: =IF($A12="","",COUNTIFS(attestations!$B$2:$B$2000,$A12,attestations!$R$2:$R$2000,"Map")) -> 3 | Q12: =IF($A12="","",COUNTIFS(attestations!$B$2:$B$2000,$A12,attestations!$R$2:$R$2000,"Image")) -> 4 | R12: =IF($A12="","",COUNTIFS(attestations!$B$2:$B$2000,$A12,attestations!$R$2:$R$2000,"Textual")) -> 9 | S12: =IF($A12="","",COUNTIFS(attestations!$B$2:$B$2000,$A12,attestations!$D$2:$D$2000,"Geometry (Setting)")) -> 9 | T12: =IF($A12="","",IF($O12>=6,"High",IF($O12>=3,"Medium",IF($O12>=1,"Low","None")))) -> High | U12: =IF($A12="","",IF(COUNTIFS(attestations!$B$2:$B$2000,$A12,attestations!$I$2:$I$2000,"Georeferenced map GCP")>0,"Y","N")) -> Y | V12: Candidate | W12: High | X12: Keystone intentional-silence case. | Y12: Town
A13: CZ-012 | B13: Gorgona | C13: Gorgona; New Gorgona | D13: Town | E13: Depopulated-not flooded | F13: 1912 depopulation order | G13: Labor | H13: Mixed | I13: pre-1844 | J13: 1912-1915 | K13: Approximate | L13: Medium | M13: =IF($A13="","",IF($L13="High","Solid point",IF($L13="Medium","Point + buffer",IF($L13="Low","Translucent area",IF($L13="Disputed","Candidate points",IF($L13="Unknown","Unplotted (unlocated panel)","-")))))) -> Point + buffer | N13: 300 | O13: =IF($A13="","",COUNTIF(attestations!$B$2:$B$2000,$A13)) -> 34 | P13: =IF($A13="","",COUNTIFS(attestations!$B$2:$B$2000,$A13,attestations!$R$2:$R$2000,"Map")) -> 4 | Q13: =IF($A13="","",COUNTIFS(attestations!$B$2:$B$2000,$A13,attestations!$R$2:$R$2000,"Image")) -> 2 | R13: =IF($A13="","",COUNTIFS(attestations!$B$2:$B$2000,$A13,attestations!$R$2:$R$2000,"Textual")) -> 8 | S13: =IF($A13="","",COUNTIFS(attestations!$B$2:$B$2000,$A13,attestations!$D$2:$D$2000,"Geometry (Setting)")) -> 8 | T13: =IF($A13="","",IF($O13>=6,"High",IF($O13>=3,"Medium",IF($O13>=1,"Low","None")))) -> High | U13: =IF($A13="","",IF(COUNTIFS(attestations!$B$2:$B$2000,$A13,attestations!$I$2:$I$2000,"Georeferenced map GCP")>0,"Y","N")) -> Y | V13: Candidate | W13: High | X13: Well-documented depopulation. | Y13: Town
A14: CZ-013 | B14: Culebra | D14: Town | E14: Depopulated-not flooded | F14: 1912 depopulation order | G14: U.S. administration | H14: Gold Roll town | I14: c.1879 | J14: 1912-1915 | K14: Approximate | L14: Medium | M14: =IF($A14="","",IF($L14="High","Solid point",IF($L14="Medium","Point + buffer",IF($L14="Low","Translucent area",IF($L14="Disputed","Candidate points",IF($L14="Unknown","Unplotted (unlocated panel)","-")))))) -> Point + buffer | N14: 300 | O14: =IF($A14="","",COUNTIF(attestations!$B$2:$B$2000,$A14)) -> 29 | P14: =IF($A14="","",COUNTIFS(attestations!$B$2:$B$2000,$A14,attestations!$R$2:$R$2000,"Map")) -> 3 | Q14: =IF($A14="","",COUNTIFS(attestations!$B$2:$B$2000,$A14,attestations!$R$2:$R$2000,"Image")) -> 1 | R14: =IF($A14="","",COUNTIFS(attestations!$B$2:$B$2000,$A14,attestations!$R$2:$R$2000,"Textual")) -> 6 | S14: =IF($A14="","",COUNTIFS(attestations!$B$2:$B$2000,$A14,attestations!$D$2:$D$2000,"Geometry (Setting)")) -> 11 | T14: =IF($A14="","",IF($O14>=6,"High",IF($O14>=3,"Medium",IF($O14>=1,"Low","None")))) -> High | U14: =IF($A14="","",IF(COUNTIFS(attestations!$B$2:$B$2000,$A14,attestations!$I$2:$I$2000,"Georeferenced map GCP")>0,"Y","N")) -> Y | V14: Candidate | W14: Medium | X14: Town vs engineering-site edge case. Start widened to c.1879: Verbrugghe 1879 (Gallica S-040) names the Cerro de la Culebra as a Wyse-Reclus survey point. [2026-09-14] | Y14: Town
A15: CZ-014 | B15: Bas Obispo | C15: Bas Obispo; Haut Obispo | D15: Construction camp | E15: Unknown | F15: Unknown | G15: Labor | H15: Mixed | I15: pre-1857 | J15: 1911-1915 | K15: Inferred | L15: Low | M15: =IF($A15="","",IF($L15="High","Solid point",IF($L15="Medium","Point + buffer",IF($L15="Low","Translucent area",IF($L15="Disputed","Candidate points",IF($L15="Unknown","Unplotted (unlocated panel)","-")))))) -> Translucent area | N15: 500 | O15: =IF($A15="","",COUNTIF(attestations!$B$2:$B$2000,$A15)) -> 29 | P15: =IF($A15="","",COUNTIFS(attestations!$B$2:$B$2000,$A15,attestations!$R$2:$R$2000,"Map")) -> 2 | Q15: =IF($A15="","",COUNTIFS(attestations!$B$2:$B$2000,$A15,attestations!$R$2:$R$2000,"Image")) -> 2 | R15: =IF($A15="","",COUNTIFS(attestations!$B$2:$B$2000,$A15,attestations!$R$2:$R$2000,"Textual")) -> 7 | S15: =IF($A15="","",COUNTIFS(attestations!$B$2:$B$2000,$A15,attestations!$D$2:$D$2000,"Geometry (Setting)")) -> 8 | T15: =IF($A15="","",IF($O15>=6,"High",IF($O15>=3,"Medium",IF($O15>=1,"Low","None")))) -> High | U15: =IF($A15="","",IF(COUNTIFS(attestations!$B$2:$B$2000,$A15,attestations!$I$2:$I$2000,"Georeferenced map GCP")>0,"Y","N")) -> Y | V15: Candidate | X15: Classify at archive. 'Haut Obispo' equated as French-era name variant (decision 2026-09-05); its 7 CA hits from 1883-10-28 belong here. Start widened to c.1895: the 1895 GORPAN survey (A-0589) already traces a built-up footprint at Bas Obispo (French-canal-era work site / old P.R.R. line). [2026-09-13 lifespan fix] Start widened c.1895 -> c.1862? 2026-09-13: the 1862 plano names 'Estacion de Obispo' at the sheet edge (A-0895) - earliest name-at-site attestation, station name only; drawn village fabric begins with the 1895 survey. | lifespan extended to dated evidence 2026-09-14 (A-1482: 'Lower Obispo' settlement drawn on the 1857 Totten map) [was: c.1862?] | end date filled 2026-09-16 (user-approved gap fix): ceased in the construction-clearance era; erasure mechanism left Unknown - the site sat higher near Gamboa and 'drowned' is not established, so no flooding is asserted | Y15: Town
A16: CZ-015 | B16: Las Cascadas | D16: Construction camp | E16: Unknown | F16: Unknown | G16: Labor | H16: Mixed | I16: c.1895 | K16: Inferred | L16: Low | M16: =IF($A16="","",IF($L16="High","Solid point",IF($L16="Medium","Point + buffer",IF($L16="Low","Translucent area",IF($L16="Disputed","Candidate points",IF($L16="Unknown","Unplotted (unlocated panel)","-")))))) -> Translucent area | N16: 500 | O16: =IF($A16="","",COUNTIF(attestations!$B$2:$B$2000,$A16)) -> 21 | P16: =IF($A16="","",COUNTIFS(attestations!$B$2:$B$2000,$A16,attestations!$R$2:$R$2000,"Map")) -> 2 | Q16: =IF($A16="","",COUNTIFS(attestations!$B$2:$B$2000,$A16,attestations!$R$2:$R$2000,"Image")) -> 1 | R16: =IF($A16="","",COUNTIFS(attestations!$B$2:$B$2000,$A16,attestations!$R$2:$R$2000,"Textual")) -> 5 | S16: =IF($A16="","",COUNTIFS(attestations!$B$2:$B$2000,$A16,attestations!$D$2:$D$2000,"Geometry (Setting)")) -> 6 | T16: =IF($A16="","",IF($O16>=6,"High",IF($O16>=3,"Medium",IF($O16>=1,"Low","None")))) -> High | U16: =IF($A16="","",IF(COUNTIFS(attestations!$B$2:$B$2000,$A16,attestations!$I$2:$I$2000,"Georeferenced map GCP")>0,"Y","N")) -> Y | V16: Candidate | X16: Start widened to c.1895: the 1895 GORPAN survey (A-0590) shows the Las Cascadas village row on the P.R.R. [2026-09-13 lifespan fix] | Y16: Town
A17: CZ-016 | B17: Bohio | C17: Bohio; Bohio Soldado | D17: Village | E17: Unknown | F17: Unknown | G17: Displacement | H17: Panamanian village | I17: pre-1850? | J17: 1911-1914 | K17: Inferred | L17: Low | M17: =IF($A17="","",IF($L17="High","Solid point",IF($L17="Medium","Point + buffer",IF($L17="Low","Translucent area",IF($L17="Disputed","Candidate points",IF($L17="Unknown","Unplotted (unlocated panel)","-")))))) -> Translucent area | N17: 500 | O17: =IF($A17="","",COUNTIF(attestations!$B$2:$B$2000,$A17)) -> 27 | P17: =IF($A17="","",COUNTIFS(attestations!$B$2:$B$2000,$A17,attestations!$R$2:$R$2000,"Map")) -> 2 | Q17: =IF($A17="","",COUNTIFS(attestations!$B$2:$B$2000,$A17,attestations!$R$2:$R$2000,"Image")) -> 1 | R17: =IF($A17="","",COUNTIFS(attestations!$B$2:$B$2000,$A17,attestations!$R$2:$R$2000,"Textual")) -> 8 | S17: =IF($A17="","",COUNTIFS(attestations!$B$2:$B$2000,$A17,attestations!$D$2:$D$2000,"Geometry (Setting)")) -> 4 | T17: =IF($A17="","",IF($O17>=6,"High",IF($O17>=3,"Medium",IF($O17>=1,"Low","None")))) -> High | U17: =IF($A17="","",IF(COUNTIFS(attestations!$B$2:$B$2000,$A17,attestations!$I$2:$I$2000,"Georeferenced map GCP")>0,"Y","N")) -> Y | V17: Candidate | X17: Likely flood-affected; verify. | end date filled 2026-09-16 (user-approved gap fix): drowned by Gatun Lake when it filled 1913-14; end matched to the submerged cohort (Matachin/Old Gatun/Frijoles) | Y17: Town
A18: CZ-101 | B18: Empire Hospital | D18: Hospital | E18: Depopulated-not flooded | F18: 1912 depopulation order | G18: U.S. administration | H18: Mixed | I18: 1906 | J18: 1916 | K18: Approximate | L18: Medium | M18: =IF($A18="","",IF($L18="High","Solid point",IF($L18="Medium","Point + buffer",IF($L18="Low","Translucent area",IF($L18="Disputed","Candidate points",IF($L18="Unknown","Unplotted (unlocated panel)","-")))))) -> Point + buffer | N18: 400 | O18: =IF($A18="","",COUNTIF(attestations!$B$2:$B$2000,$A18)) -> 5 | P18: =IF($A18="","",COUNTIFS(attestations!$B$2:$B$2000,$A18,attestations!$R$2:$R$2000,"Map")) -> 1 | Q18: =IF($A18="","",COUNTIFS(attestations!$B$2:$B$2000,$A18,attestations!$R$2:$R$2000,"Image")) -> 0 | R18: =IF($A18="","",COUNTIFS(attestations!$B$2:$B$2000,$A18,attestations!$R$2:$R$2000,"Textual")) -> 1 | S18: =IF($A18="","",COUNTIFS(attestations!$B$2:$B$2000,$A18,attestations!$D$2:$D$2000,"Geometry (Setting)")) -> 1 | T18: =IF($A18="","",IF($O18>=6,"High",IF($O18>=3,"Medium",IF($O18>=1,"Low","None")))) -> Medium | U18: =IF($A18="","",IF(COUNTIFS(attestations!$B$2:$B$2000,$A18,attestations!$I$2:$I$2000,"Georeferenced map GCP")>0,"Y","N")) -> Y | V18: Candidate | X18: ICC hospital. | 2026-09-14: A-0041 retracted - the hospital has NO cartographic attestation on any sheet in hand; text-only place (Canal Record 1907). Placeholder coordinate and missing footprint are the honest record. | Y18: Site/Institution | Z18: CZ-011
A19: CZ-102 | B19: Empire Commissary | D19: Commissary/Supermarket | E19: Depopulated-not flooded | F19: 1912 depopulation order | G19: U.S. administration | H19: Mixed | I19: 1906 | J19: 1916 | K19: Approximate | L19: Medium | M19: =IF($A19="","",IF($L19="High","Solid point",IF($L19="Medium","Point + buffer",IF($L19="Low","Translucent area",IF($L19="Disputed","Candidate points",IF($L19="Unknown","Unplotted (unlocated panel)","-")))))) -> Point + buffer | N19: 400 | O19: =IF($A19="","",COUNTIF(attestations!$B$2:$B$2000,$A19)) -> 5 | P19: =IF($A19="","",COUNTIFS(attestations!$B$2:$B$2000,$A19,attestations!$R$2:$R$2000,"Map")) -> 0 | Q19: =IF($A19="","",COUNTIFS(attestations!$B$2:$B$2000,$A19,attestations!$R$2:$R$2000,"Image")) -> 0 | R19: =IF($A19="","",COUNTIFS(attestations!$B$2:$B$2000,$A19,attestations!$R$2:$R$2000,"Textual")) -> 1 | S19: =IF($A19="","",COUNTIFS(attestations!$B$2:$B$2000,$A19,attestations!$D$2:$D$2000,"Geometry (Setting)")) -> 1 | T19: =IF($A19="","",IF($O19>=6,"High",IF($O19>=3,"Medium",IF($O19>=1,"Low","None")))) -> Medium | U19: =IF($A19="","",IF(COUNTIFS(attestations!$B$2:$B$2000,$A19,attestations!$I$2:$I$2000,"Georeferenced map GCP")>0,"Y","N")) -> Y | V19: Candidate | X19: ICC commissary / store. Building outline traced 2026-09-13 from the source sheet into data/footprints.geojson (building-outline pass). | Y19: Site/Institution | Z19: CZ-011
A20: CZ-103 | B20: Empire Clubhouse & Cinema | D20: Cinema/Clubhouse | E20: Depopulated-not flooded | F20: 1912 depopulation order | G20: U.S. administration | H20: Gold Roll town | I20: 1907 | J20: 1916 | K20: Approximate | L20: Medium | M20: =IF($A20="","",IF($L20="High","Solid point",IF($L20="Medium","Point + buffer",IF($L20="Low","Translucent area",IF($L20="Disputed","Candidate points",IF($L20="Unknown","Unplotted (unlocated panel)","-")))))) -> Point + buffer | N20: 400 | O20: =IF($A20="","",COUNTIF(attestations!$B$2:$B$2000,$A20)) -> 1 | P20: =IF($A20="","",COUNTIFS(attestations!$B$2:$B$2000,$A20,attestations!$R$2:$R$2000,"Map")) -> 0 | Q20: =IF($A20="","",COUNTIFS(attestations!$B$2:$B$2000,$A20,attestations!$R$2:$R$2000,"Image")) -> 0 | R20: =IF($A20="","",COUNTIFS(attestations!$B$2:$B$2000,$A20,attestations!$R$2:$R$2000,"Textual")) -> 0 | S20: =IF($A20="","",COUNTIFS(attestations!$B$2:$B$2000,$A20,attestations!$D$2:$D$2000,"Geometry (Setting)")) -> 0 | T20: =IF($A20="","",IF($O20>=6,"High",IF($O20>=3,"Medium",IF($O20>=1,"Low","None")))) -> Low | U20: =IF($A20="","",IF(COUNTIFS(attestations!$B$2:$B$2000,$A20,attestations!$I$2:$I$2000,"Georeferenced map GCP")>0,"Y","N")) -> N | V20: Duplicate | X20: Gold-roll amenity. | MERGED into CZ-125 2026-09-14: the Canal Record 'Clubhouse' and the plan's Y.M.C.A. are the same institution (ICC clubhouses were YMCA-operated; full-sheet sweep found no separate Clubhouse label). Row kept for id stability - do not use. | Y20: Building | Z20: CZ-011
A21: CZ-104 | B21: Empire Silver Quarters | D21: Quarters/Housing | E21: Depopulated-not flooded | F21: 1912 depopulation order | G21: Labor | H21: West Indian / Silver Roll | I21: 1905 | J21: 1916 | K21: Approximate | L21: Low | M21: =IF($A21="","",IF($L21="High","Solid point",IF($L21="Medium","Point + buffer",IF($L21="Low","Translucent area",IF($L21="Disputed","Candidate points",IF($L21="Unknown","Unplotted (unlocated panel)","-")))))) -> Translucent area | N21: 400 | O21: =IF($A21="","",COUNTIF(attestations!$B$2:$B$2000,$A21)) -> 9 | P21: =IF($A21="","",COUNTIFS(attestations!$B$2:$B$2000,$A21,attestations!$R$2:$R$2000,"Map")) -> 1 | Q21: =IF($A21="","",COUNTIFS(attestations!$B$2:$B$2000,$A21,attestations!$R$2:$R$2000,"Image")) -> 0 | R21: =IF($A21="","",COUNTIFS(attestations!$B$2:$B$2000,$A21,attestations!$R$2:$R$2000,"Textual")) -> 1 | S21: =IF($A21="","",COUNTIFS(attestations!$B$2:$B$2000,$A21,attestations!$D$2:$D$2000,"Geometry (Setting)")) -> 0 | T21: =IF($A21="","",IF($O21>=6,"High",IF($O21>=3,"Medium",IF($O21>=1,"Low","None")))) -> High | U21: =IF($A21="","",IF(COUNTIFS(attestations!$B$2:$B$2000,$A21,attestations!$I$2:$I$2000,"Georeferenced map GCP")>0,"Y","N")) -> N | V21: Candidate | W21: High | X21: Silver-roll housing; thinly mapped. | Y21: Neighborhood | Z21: CZ-011
A22: CZ-105 | B22: Empire Gold Quarters | D22: Quarters/Housing | E22: Depopulated-not flooded | F22: 1912 depopulation order | G22: U.S. administration | H22: Gold Roll town | I22: 1905 | J22: 1916 | K22: Approximate | L22: Medium | M22: =IF($A22="","",IF($L22="High","Solid point",IF($L22="Medium","Point + buffer",IF($L22="Low","Translucent area",IF($L22="Disputed","Candidate points",IF($L22="Unknown","Unplotted (unlocated panel)","-")))))) -> Point + buffer | N22: 400 | O22: =IF($A22="","",COUNTIF(attestations!$B$2:$B$2000,$A22)) -> 8 | P22: =IF($A22="","",COUNTIFS(attestations!$B$2:$B$2000,$A22,attestations!$R$2:$R$2000,"Map")) -> 1 | Q22: =IF($A22="","",COUNTIFS(attestations!$B$2:$B$2000,$A22,attestations!$R$2:$R$2000,"Image")) -> 0 | R22: =IF($A22="","",COUNTIFS(attestations!$B$2:$B$2000,$A22,attestations!$R$2:$R$2000,"Textual")) -> 0 | S22: =IF($A22="","",COUNTIFS(attestations!$B$2:$B$2000,$A22,attestations!$D$2:$D$2000,"Geometry (Setting)")) -> 1 | T22: =IF($A22="","",IF($O22>=6,"High",IF($O22>=3,"Medium",IF($O22>=1,"Low","None")))) -> High | U22: =IF($A22="","",IF(COUNTIFS(attestations!$B$2:$B$2000,$A22,attestations!$I$2:$I$2000,"Georeferenced map GCP")>0,"Y","N")) -> Y | V22: Candidate | X22: Gold-roll housing. | Y22: Neighborhood | Z22: CZ-011
A23: CZ-106 | B23: Empire Plaza | D23: Park/Plaza | E23: Depopulated-not flooded | F23: 1912 depopulation order | G23: Other | H23: Mixed | I23: 1885 | J23: 1916 | K23: Approximate | L23: Medium | M23: =IF($A23="","",IF($L23="High","Solid point",IF($L23="Medium","Point + buffer",IF($L23="Low","Translucent area",IF($L23="Disputed","Candidate points",IF($L23="Unknown","Unplotted (unlocated panel)","-")))))) -> Point + buffer | N23: 400 | O23: =IF($A23="","",COUNTIF(attestations!$B$2:$B$2000,$A23)) -> 0 | P23: =IF($A23="","",COUNTIFS(attestations!$B$2:$B$2000,$A23,attestations!$R$2:$R$2000,"Map")) -> 0 | Q23: =IF($A23="","",COUNTIFS(attestations!$B$2:$B$2000,$A23,attestations!$R$2:$R$2000,"Image")) -> 0 | R23: =IF($A23="","",COUNTIFS(attestations!$B$2:$B$2000,$A23,attestations!$R$2:$R$2000,"Textual")) -> 0 | S23: =IF($A23="","",COUNTIFS(attestations!$B$2:$B$2000,$A23,attestations!$D$2:$D$2000,"Geometry (Setting)")) -> 0 | T23: =IF($A23="","",IF($O23>=6,"High",IF($O23>=3,"Medium",IF($O23>=1,"Low","None")))) -> None | U23: =IF($A23="","",IF(COUNTIFS(attestations!$B$2:$B$2000,$A23,attestations!$I$2:$I$2000,"Georeferenced map GCP")>0,"Y","N")) -> N | V23: Duplicate | X23: Central open space, inferred from a 'Band Stand' label read on the MIRRORED EMPIRE warp; the corrected warp reads 'Grand Stand' at the ballpark. MERGED into CZ-120 2026-09-13; the traced grandstand outline is attached to CZ-120. Row kept for id stability - do not use. | Y23: Site/Institution | Z23: CZ-011
A24: CZ-201 | B24: Nuevo Emperador (present-day) | C24: Emperador | D24: Modern town | E24: Persists | F24: Other | G24: Other | H24: Mixed | I24: pre-1994? | K24: Unknown | L24: Unknown | M24: =IF($A24="","",IF($L24="High","Solid point",IF($L24="Medium","Point + buffer",IF($L24="Low","Translucent area",IF($L24="Disputed","Candidate points",IF($L24="Unknown","Unplotted (unlocated panel)","-")))))) -> Unplotted (unlocated panel) | N24: 100 | O24: =IF($A24="","",COUNTIF(attestations!$B$2:$B$2000,$A24)) -> 1 | P24: =IF($A24="","",COUNTIFS(attestations!$B$2:$B$2000,$A24,attestations!$R$2:$R$2000,"Map")) -> 0 | Q24: =IF($A24="","",COUNTIFS(attestations!$B$2:$B$2000,$A24,attestations!$R$2:$R$2000,"Image")) -> 0 | R24: =IF($A24="","",COUNTIFS(attestations!$B$2:$B$2000,$A24,attestations!$R$2:$R$2000,"Textual")) -> 0 | S24: =IF($A24="","",COUNTIFS(attestations!$B$2:$B$2000,$A24,attestations!$D$2:$D$2000,"Geometry (Setting)")) -> 0 | T24: =IF($A24="","",IF($O24>=6,"High",IF($O24>=3,"Medium",IF($O24>=1,"Low","None")))) -> Low | U24: =IF($A24="","",IF(COUNTIFS(attestations!$B$2:$B$2000,$A24,attestations!$I$2:$I$2000,"Georeferenced map GCP")>0,"Y","N")) -> N | V24: Candidate | X24: Present-day settlement; illustrative. | ERASED 2026-09-14: unverified illustrative example removed from the model - not a duplicate; the export's Duplicate skip is reused for row-position stability. The palimpsest now rests on the verified extant places only. Do not use. | RESTORED 2026-09-14 as honest UNLOCATED extant: the town exists - existence attested by 1990s AP datelines 'NUEVO EMPERADOR, Panama' (dLOC) - but the old record's coordinate and founding were invented, so both are withdrawn [start was: 1955]. Coordinates enter only from a citable present-day source. | Y24: Town | Z24: CZ-011 | AA24: Present-day town. 1990s newspaper datelines confirm it exists, but no citable source yet gives its location or founding date.
A25: CZ-202 | B25: Modern roadway segment | D25: Modern infrastructure | E25: Persists | F25: Other | G25: Infrastructure | H25: Mixed | I25: 1950 | K25: Inferred | L25: Medium | M25: =IF($A25="","",IF($L25="High","Solid point",IF($L25="Medium","Point + buffer",IF($L25="Low","Translucent area",IF($L25="Disputed","Candidate points",IF($L25="Unknown","Unplotted (unlocated panel)","-")))))) -> Point + buffer | N25: 100 | O25: =IF($A25="","",COUNTIF(attestations!$B$2:$B$2000,$A25)) -> 0 | P25: =IF($A25="","",COUNTIFS(attestations!$B$2:$B$2000,$A25,attestations!$R$2:$R$2000,"Map")) -> 0 | Q25: =IF($A25="","",COUNTIFS(attestations!$B$2:$B$2000,$A25,attestations!$R$2:$R$2000,"Image")) -> 0 | R25: =IF($A25="","",COUNTIFS(attestations!$B$2:$B$2000,$A25,attestations!$R$2:$R$2000,"Textual")) -> 0 | S25: =IF($A25="","",COUNTIFS(attestations!$B$2:$B$2000,$A25,attestations!$D$2:$D$2000,"Geometry (Setting)")) -> 0 | T25: =IF($A25="","",IF($O25>=6,"High",IF($O25>=3,"Medium",IF($O25>=1,"Low","None")))) -> None | U25: =IF($A25="","",IF(COUNTIFS(attestations!$B$2:$B$2000,$A25,attestations!$I$2:$I$2000,"Georeferenced map GCP")>0,"Y","N")) -> N | V25: Duplicate | X25: Present-day road; illustrative. | ERASED 2026-09-14: unverified illustrative example removed from the model - not a duplicate; the export's Duplicate skip is reused for row-position stability. The palimpsest now rests on the verified extant places only. Do not use. | Y25: Infrastructure | Z25: CZ-011
A26: CZ-107 | B26: Empire Church / Chapel | D26: Church | E26: Depopulated-not flooded | F26: 1912 depopulation order | G26: Afro-Caribbean life | H26: West Indian / Silver Roll | I26: 1906 | J26: 1916 | K26: Approximate | L26: Medium | M26: =IF($A26="","",IF($L26="High","Solid point",IF($L26="Medium","Point + buffer",IF($L26="Low","Translucent area",IF($L26="Disputed","Candidate points",IF($L26="Unknown","Unplotted (unlocated panel)","-")))))) -> Point + buffer | N26: 400 | O26: =IF($A26="","",COUNTIF(attestations!$B$2:$B$2000,$A26)) -> 9 | P26: =IF($A26="","",COUNTIFS(attestations!$B$2:$B$2000,$A26,attestations!$R$2:$R$2000,"Map")) -> 0 | Q26: =IF($A26="","",COUNTIFS(attestations!$B$2:$B$2000,$A26,attestations!$R$2:$R$2000,"Image")) -> 0 | R26: =IF($A26="","",COUNTIFS(attestations!$B$2:$B$2000,$A26,attestations!$R$2:$R$2000,"Textual")) -> 1 | S26: =IF($A26="","",COUNTIFS(attestations!$B$2:$B$2000,$A26,attestations!$D$2:$D$2000,"Geometry (Setting)")) -> 1 | T26: =IF($A26="","",IF($O26>=6,"High",IF($O26>=3,"Medium",IF($O26>=1,"Low","None")))) -> High | U26: =IF($A26="","",IF(COUNTIFS(attestations!$B$2:$B$2000,$A26,attestations!$I$2:$I$2000,"Georeferenced map GCP")>0,"Y","N")) -> Y | V26: Candidate | X26: West Indian chapel. | Y26: Site/Institution | Z26: CZ-011
A27: CZ-108 | B27: Empire Cemetery | D27: Cemetery | E27: Depopulated-not flooded | F27: 1912 depopulation order | G27: Afro-Caribbean life | H27: West Indian / Silver Roll | I27: 1905 | J27: 1916 | K27: Inferred | L27: Low | M27: =IF($A27="","",IF($L27="High","Solid point",IF($L27="Medium","Point + buffer",IF($L27="Low","Translucent area",IF($L27="Disputed","Candidate points",IF($L27="Unknown","Unplotted (unlocated panel)","-")))))) -> Translucent area | N27: 400 | O27: =IF($A27="","",COUNTIF(attestations!$B$2:$B$2000,$A27)) -> 7 | P27: =IF($A27="","",COUNTIFS(attestations!$B$2:$B$2000,$A27,attestations!$R$2:$R$2000,"Map")) -> 1 | Q27: =IF($A27="","",COUNTIFS(attestations!$B$2:$B$2000,$A27,attestations!$R$2:$R$2000,"Image")) -> 0 | R27: =IF($A27="","",COUNTIFS(attestations!$B$2:$B$2000,$A27,attestations!$R$2:$R$2000,"Textual")) -> 0 | S27: =IF($A27="","",COUNTIFS(attestations!$B$2:$B$2000,$A27,attestations!$D$2:$D$2000,"Geometry (Setting)")) -> 0 | T27: =IF($A27="","",IF($O27>=6,"High",IF($O27>=3,"Medium",IF($O27>=1,"Low","None")))) -> High | U27: =IF($A27="","",IF(COUNTIFS(attestations!$B$2:$B$2000,$A27,attestations!$I$2:$I$2000,"Georeferenced map GCP")>0,"Y","N")) -> N | V27: Candidate | W27: High | X27: Afro-Caribbean burial ground; rarely on official maps. | Y27: Site/Institution | Z27: CZ-011
A28: CZ-109 | B28: Empire School | D28: School | E28: Depopulated-not flooded | F28: 1912 depopulation order | G28: U.S. administration | H28: Mixed | I28: 1906 | J28: 1916 | K28: Approximate | L28: Medium | M28: =IF($A28="","",IF($L28="High","Solid point",IF($L28="Medium","Point + buffer",IF($L28="Low","Translucent area",IF($L28="Disputed","Candidate points",IF($L28="Unknown","Unplotted (unlocated panel)","-")))))) -> Point + buffer | N28: 400 | O28: =IF($A28="","",COUNTIF(attestations!$B$2:$B$2000,$A28)) -> 5 | P28: =IF($A28="","",COUNTIFS(attestations!$B$2:$B$2000,$A28,attestations!$R$2:$R$2000,"Map")) -> 0 | Q28: =IF($A28="","",COUNTIFS(attestations!$B$2:$B$2000,$A28,attestations!$R$2:$R$2000,"Image")) -> 0 | R28: =IF($A28="","",COUNTIFS(attestations!$B$2:$B$2000,$A28,attestations!$R$2:$R$2000,"Textual")) -> 1 | S28: =IF($A28="","",COUNTIFS(attestations!$B$2:$B$2000,$A28,attestations!$D$2:$D$2000,"Geometry (Setting)")) -> 1 | T28: =IF($A28="","",IF($O28>=6,"High",IF($O28>=3,"Medium",IF($O28>=1,"Low","None")))) -> Medium | U28: =IF($A28="","",IF(COUNTIFS(attestations!$B$2:$B$2000,$A28,attestations!$I$2:$I$2000,"Georeferenced map GCP")>0,"Y","N")) -> Y | V28: Candidate | X28: Canal Zone school. Building outline traced 2026-09-13 from the source sheet into data/footprints.geojson (building-outline pass). | Y28: Site/Institution | Z28: CZ-011
A29: CZ-017 | B29: Cristobal | D29: Town | E29: Persists | F29: Other | G29: U.S. administration | H29: Mixed | I29: c.1855 | K29: Approximate | L29: Medium | M29: =IF($A29="","",IF($L29="High","Solid point",IF($L29="Medium","Point + buffer",IF($L29="Low","Translucent area",IF($L29="Disputed","Candidate points",IF($L29="Unknown","Unplotted (unlocated panel)","-")))))) -> Point + buffer | N29: 300 | O29: =IF($A29="","",COUNTIF(attestations!$B$2:$B$2000,$A29)) -> 22 | P29: =IF($A29="","",COUNTIFS(attestations!$B$2:$B$2000,$A29,attestations!$R$2:$R$2000,"Map")) -> 1 | Q29: =IF($A29="","",COUNTIFS(attestations!$B$2:$B$2000,$A29,attestations!$R$2:$R$2000,"Image")) -> 3 | R29: =IF($A29="","",COUNTIFS(attestations!$B$2:$B$2000,$A29,attestations!$R$2:$R$2000,"Textual")) -> 5 | S29: =IF($A29="","",COUNTIFS(attestations!$B$2:$B$2000,$A29,attestations!$D$2:$D$2000,"Geometry (Setting)")) -> 6 | T29: =IF($A29="","",IF($O29>=6,"High",IF($O29>=3,"Medium",IF($O29>=1,"Low","None")))) -> High | U29: =IF($A29="","",IF(COUNTIFS(attestations!$B$2:$B$2000,$A29,attestations!$I$2:$I$2000,"Georeferenced map GCP")>0,"Y","N")) -> Y | V29: Candidate | W29: Medium | X29: Atlantic terminal town adjoining Colon. In official CZ post-office list (Evening Star 1906-02-16). 9,994 Chronicling America hits from 1880-01-27. | Y29: Town | AA29: The canal's Atlantic terminal town, next to the Panamanian city of Colón.
A30: CZ-018 | B30: Ancon | D30: Town | E30: Persists | F30: Other | G30: U.S. administration | H30: Mixed | I30: c.1880 | K30: Approximate | L30: Medium | M30: =IF($A30="","",IF($L30="High","Solid point",IF($L30="Medium","Point + buffer",IF($L30="Low","Translucent area",IF($L30="Disputed","Candidate points",IF($L30="Unknown","Unplotted (unlocated panel)","-")))))) -> Point + buffer | N30: 300 | O30: =IF($A30="","",COUNTIF(attestations!$B$2:$B$2000,$A30)) -> 19 | P30: =IF($A30="","",COUNTIFS(attestations!$B$2:$B$2000,$A30,attestations!$R$2:$R$2000,"Map")) -> 1 | Q30: =IF($A30="","",COUNTIFS(attestations!$B$2:$B$2000,$A30,attestations!$R$2:$R$2000,"Image")) -> 1 | R30: =IF($A30="","",COUNTIFS(attestations!$B$2:$B$2000,$A30,attestations!$R$2:$R$2000,"Textual")) -> 5 | S30: =IF($A30="","",COUNTIFS(attestations!$B$2:$B$2000,$A30,attestations!$D$2:$D$2000,"Geometry (Setting)")) -> 5 | T30: =IF($A30="","",IF($O30>=6,"High",IF($O30>=3,"Medium",IF($O30>=1,"Low","None")))) -> High | U30: =IF($A30="","",IF(COUNTIFS(attestations!$B$2:$B$2000,$A30,attestations!$I$2:$I$2000,"Georeferenced map GCP")>0,"Y","N")) -> Y | V30: Candidate | W30: Medium | X30: ICC headquarters / hospital town. 1906 post-office list. 7,063 CA hits from 1880-01-07. | Y30: Town | AA30: Headquarters and hospital town of the Isthmian Canal Commission, the US agency that built the canal.
A31: CZ-019 | B31: Rio Grande | D31: Village | E31: Depopulated-not flooded | F31: 1912 depopulation order | G31: Displacement | H31: Mixed | I31: pre-1857 | J31: 1912 | K31: Approximate | L31: Medium | M31: =IF($A31="","",IF($L31="High","Solid point",IF($L31="Medium","Point + buffer",IF($L31="Low","Translucent area",IF($L31="Disputed","Candidate points",IF($L31="Unknown","Unplotted (unlocated panel)","-")))))) -> Point + buffer | N31: 300 | O31: =IF($A31="","",COUNTIF(attestations!$B$2:$B$2000,$A31)) -> 16 | P31: =IF($A31="","",COUNTIFS(attestations!$B$2:$B$2000,$A31,attestations!$R$2:$R$2000,"Map")) -> 1 | Q31: =IF($A31="","",COUNTIFS(attestations!$B$2:$B$2000,$A31,attestations!$R$2:$R$2000,"Image")) -> 1 | R31: =IF($A31="","",COUNTIFS(attestations!$B$2:$B$2000,$A31,attestations!$R$2:$R$2000,"Textual")) -> 5 | S31: =IF($A31="","",COUNTIFS(attestations!$B$2:$B$2000,$A31,attestations!$D$2:$D$2000,"Geometry (Setting)")) -> 5 | T31: =IF($A31="","",IF($O31>=6,"High",IF($O31>=3,"Medium",IF($O31>=1,"Low","None")))) -> High | U31: =IF($A31="","",IF(COUNTIFS(attestations!$B$2:$B$2000,$A31,attestations!$I$2:$I$2000,"Georeferenced map GCP")>0,"Y","N")) -> Y | V31: Candidate | W31: High | X31: Commissary settlement abandoned 1912 as canal advanced (Der Seebote 1913-05-18). Absent from prior gazetteer; 2,727 CA hits. CAUTION: also a river name. | lifespan extended to dated evidence 2026-09-14 (A-1487: Rio Grande Station lettering on the 1857 Totten map) [was: c.1880?] | Y31: Town
A32: CZ-020 | B32: Pedro Miguel | D32: Town | E32: Persists | F32: Other | G32: Infrastructure | H32: Mixed | I32: c.1855 | K32: Approximate | L32: Medium | M32: =IF($A32="","",IF($L32="High","Solid point",IF($L32="Medium","Point + buffer",IF($L32="Low","Translucent area",IF($L32="Disputed","Candidate points",IF($L32="Unknown","Unplotted (unlocated panel)","-")))))) -> Point + buffer | N32: 300 | O32: =IF($A32="","",COUNTIF(attestations!$B$2:$B$2000,$A32)) -> 24 | P32: =IF($A32="","",COUNTIFS(attestations!$B$2:$B$2000,$A32,attestations!$R$2:$R$2000,"Map")) -> 2 | Q32: =IF($A32="","",COUNTIFS(attestations!$B$2:$B$2000,$A32,attestations!$R$2:$R$2000,"Image")) -> 1 | R32: =IF($A32="","",COUNTIFS(attestations!$B$2:$B$2000,$A32,attestations!$R$2:$R$2000,"Textual")) -> 6 | S32: =IF($A32="","",COUNTIFS(attestations!$B$2:$B$2000,$A32,attestations!$D$2:$D$2000,"Geometry (Setting)")) -> 9 | T32: =IF($A32="","",IF($O32>=6,"High",IF($O32>=3,"Medium",IF($O32>=1,"Low","None")))) -> High | U32: =IF($A32="","",IF(COUNTIFS(attestations!$B$2:$B$2000,$A32,attestations!$I$2:$I$2000,"Georeferenced map GCP")>0,"Y","N")) -> Y | V32: Candidate | W32: Medium | X32: Lock town. 1906 post-office list; 1897 lock-plan article. 2,311 CA hits. | RULING 2026-09-13: split old/new - CZ-172 'Pedro Miguel (as-built)' now carries the 1911 property-block town; this id keeps the old (PRR-era) village. | Y32: Town | AA32: Village on the Panama Railroad line, later a lock town. The town laid out on the 1911 property map is recorded as a separate place.
A33: CZ-021 | B33: La Boca | D33: Town | E33: Relocated | F33: Other | G33: Afro-Caribbean life | H33: West Indian / Silver Roll | I33: c.1880 | K33: Approximate | L33: Medium | M33: =IF($A33="","",IF($L33="High","Solid point",IF($L33="Medium","Point + buffer",IF($L33="Low","Translucent area",IF($L33="Disputed","Candidate points",IF($L33="Unknown","Unplotted (unlocated panel)","-")))))) -> Point + buffer | N33: 300 | O33: =IF($A33="","",COUNTIF(attestations!$B$2:$B$2000,$A33)) -> 22 | P33: =IF($A33="","",COUNTIFS(attestations!$B$2:$B$2000,$A33,attestations!$R$2:$R$2000,"Map")) -> 2 | Q33: =IF($A33="","",COUNTIFS(attestations!$B$2:$B$2000,$A33,attestations!$R$2:$R$2000,"Image")) -> 1 | R33: =IF($A33="","",COUNTIFS(attestations!$B$2:$B$2000,$A33,attestations!$R$2:$R$2000,"Textual")) -> 6 | S33: =IF($A33="","",COUNTIFS(attestations!$B$2:$B$2000,$A33,attestations!$D$2:$D$2000,"Geometry (Setting)")) -> 5 | T33: =IF($A33="","",IF($O33>=6,"High",IF($O33>=3,"Medium",IF($O33>=1,"Low","None")))) -> High | U33: =IF($A33="","",IF(COUNTIFS(attestations!$B$2:$B$2000,$A33,attestations!$I$2:$I$2000,"Georeferenced map GCP")>0,"Y","N")) -> Y | V33: Candidate | W33: High | X33: Pacific terminal / silver town; renamed and absorbed into Balboa c.1909. 1906 post-office list; 1887 French works table. 2,173 CA hits. [2026-09-12 RULING: 1947 'La Boca' = same place resumed; end date reopened - name suppressed on official maps c.1908-1940s while site labeled Balboa, community persisted.] | Y33: Town
A34: CZ-022 | B34: Corozal | D34: Town | E34: Persists | F34: Other | G34: U.S. administration | H34: Mixed | I34: c.1880 | K34: Approximate | L34: Medium | M34: =IF($A34="","",IF($L34="High","Solid point",IF($L34="Medium","Point + buffer",IF($L34="Low","Translucent area",IF($L34="Disputed","Candidate points",IF($L34="Unknown","Unplotted (unlocated panel)","-")))))) -> Point + buffer | N34: 300 | O34: =IF($A34="","",COUNTIF(attestations!$B$2:$B$2000,$A34)) -> 20 | P34: =IF($A34="","",COUNTIFS(attestations!$B$2:$B$2000,$A34,attestations!$R$2:$R$2000,"Map")) -> 2 | Q34: =IF($A34="","",COUNTIFS(attestations!$B$2:$B$2000,$A34,attestations!$R$2:$R$2000,"Image")) -> 1 | R34: =IF($A34="","",COUNTIFS(attestations!$B$2:$B$2000,$A34,attestations!$R$2:$R$2000,"Textual")) -> 6 | S34: =IF($A34="","",COUNTIFS(attestations!$B$2:$B$2000,$A34,attestations!$D$2:$D$2000,"Geometry (Setting)")) -> 6 | T34: =IF($A34="","",IF($O34>=6,"High",IF($O34>=3,"Medium",IF($O34>=1,"Low","None")))) -> High | U34: =IF($A34="","",IF(COUNTIFS(attestations!$B$2:$B$2000,$A34,attestations!$I$2:$I$2000,"Georeferenced map GCP")>0,"Y","N")) -> Y | V34: Candidate | W34: Medium | X34: 1906 post-office list; 1887 French works table (OCR 'Corvzal'). 768 CA hits. | Y34: Town
A35: CZ-023 | B35: Frijoles | D35: Station | E35: Submerged | F35: Gatun Lake flooding | G35: Displacement | H35: Panamanian village | I35: c.1855 | J35: 1911-1914 | K35: Approximate | L35: Medium | M35: =IF($A35="","",IF($L35="High","Solid point",IF($L35="Medium","Point + buffer",IF($L35="Low","Translucent area",IF($L35="Disputed","Candidate points",IF($L35="Unknown","Unplotted (unlocated panel)","-")))))) -> Point + buffer | N35: 250 | O35: =IF($A35="","",COUNTIF(attestations!$B$2:$B$2000,$A35)) -> 17 | P35: =IF($A35="","",COUNTIFS(attestations!$B$2:$B$2000,$A35,attestations!$R$2:$R$2000,"Map")) -> 2 | Q35: =IF($A35="","",COUNTIFS(attestations!$B$2:$B$2000,$A35,attestations!$R$2:$R$2000,"Image")) -> 1 | R35: =IF($A35="","",COUNTIFS(attestations!$B$2:$B$2000,$A35,attestations!$R$2:$R$2000,"Textual")) -> 4 | S35: =IF($A35="","",COUNTIFS(attestations!$B$2:$B$2000,$A35,attestations!$D$2:$D$2000,"Geometry (Setting)")) -> 6 | T35: =IF($A35="","",IF($O35>=6,"High",IF($O35>=3,"Medium",IF($O35>=1,"Low","None")))) -> High | U35: =IF($A35="","",IF(COUNTIFS(attestations!$B$2:$B$2000,$A35,attestations!$I$2:$I$2000,"Georeferenced map GCP")>0,"Y","N")) -> Y | V35: Candidate | W35: High | X35: PRR station; old site flooded by Gatun Lake, station relocated. 1882 French brigade list; 1906 post offices. CAUTION: also a river name. 370 CA hits. | RULING 2026-09-13: split old/new - CZ-173 'New Frijoles' now carries the relocated-line station (c.1909-, persists); this id keeps the drowned PRR village, lifespan c.1855-1911/14 stands. The 1940 census read moved with the split - the lifespan DATA HEALTH flag is thereby resolved. | Y35: Town
